<?xml version="1.0" encoding="utf-8"?>
<!-- This URDF was automatically created by SolidWorks to URDF Exporter! Originally created by Stephen Brawner (brawner@gmail.com) 
     Commit Version: 1.6.0-4-g7f85cfe  Build Version: 1.6.7995.38578
     For more information, please see http://wiki.ros.org/sw_urdf_exporter -->
<robot
  name="mycar00">
  <link
    name="base_link">
    <inertial>
      <origin
        xyz="0.0100653264444975 0.000860552157373518 -0.00979527824108568"
        rpy="0 0 0" />
      <mass
        value="0.40524308710052" />
      <inertia
        ixx="0.000263972276545947"
        ixy="2.34762938188814E-07"
        ixz="2.10590388351321E-06"
        iyy="0.000536095284849452"
        iyz="5.021919699154E-07"
        izz="0.000750273841413584" />
    </inertial>
    <visual>
      <origin
        xyz="0 0 0"
        rpy="0 0 0" />
      <geometry>
        <mesh
          filename="package://mycar00/meshes/base_link.STL" />
      </geometry>
      <material
        name="">
        <color
          rgba="1 0.937254901960784 0.137254901960784 1" />
      </material>
    </visual>
    <collision>
      <origin
        xyz="0 0 0"
        rpy="0 0 0" />
      <geometry>
        <mesh
          filename="package://mycar00/meshes/base_link.STL" />
      </geometry>
    </collision>
  </link>
  <link
    name="fl_Link">
    <inertial>
      <origin
        xyz="7.83044107471875E-08 -0.00156153692652505 5.5525919903654E-09"
        rpy="0 0 0" />
      <mass
        value="0.0602360435887033" />
      <inertia
        ixx="2.53145471001937E-05"
        ixy="1.13031218397668E-11"
        ixz="-6.0257647754974E-09"
        iyy="4.43444324168367E-05"
        iyz="-1.87112192685036E-12"
        izz="2.53249491202015E-05" />
    </inertial>
    <visual>
      <origin
        xyz="0 0 0"
        rpy="0 0 0" />
      <geometry>
        <mesh
          filename="package://mycar00/meshes/fl_Link.STL" />
      </geometry>
      <material
        name="">
        <color
          rgba="1 1 1 1" />
      </material>
    </visual>
    <collision>
      <origin
        xyz="0 0 0"
        rpy="0 0 0" />
      <geometry>
        <mesh
          filename="package://mycar00/meshes/fl_Link.STL" />
      </geometry>
    </collision>
  </link>
  <joint
    name="fl_joint"
    type="continuous">
    <origin
      xyz="0.0798768641582343 0.0869186409566084 -0.0315000000000001"
      rpy="0 0 0" />
    <parent
      link="base_link" />
    <child
      link="fl_Link" />
    <axis
      xyz="0 1 0" />
  </joint>
  <link
    name="fr_Link">
    <inertial>
      <origin
        xyz="5.51029846751483E-10 0.00156153692869208 -7.89385122268449E-08"
        rpy="0 0 0" />
      <mass
        value="0.0602360436323037" />
      <inertia
        ixx="2.53258094520077E-05"
        ixy="-2.72202970171872E-12"
        ixz="-5.15951627852449E-09"
        iyy="4.43444324398627E-05"
        iyz="1.08051357520254E-11"
        izz="2.53136867926222E-05" />
    </inertial>
    <visual>
      <origin
        xyz="0 0 0"
        rpy="0 0 0" />
      <geometry>
        <mesh
          filename="package://mycar00/meshes/fr_Link.STL" />
      </geometry>
      <material
        name="">
        <color
          rgba="1 1 1 1" />
      </material>
    </visual>
    <collision>
      <origin
        xyz="0 0 0"
        rpy="0 0 0" />
      <geometry>
        <mesh
          filename="package://mycar00/meshes/fr_Link.STL" />
      </geometry>
    </collision>
  </link>
  <joint
    name="fr_joint"
    type="continuous">
    <origin
      xyz="0.0798768641582345 -0.0862813590433905 -0.0314999999999999"
      rpy="0 0 0" />
    <parent
      link="base_link" />
    <child
      link="fr_Link" />
    <axis
      xyz="0 1 0" />
  </joint>
  <link
    name="br_Link">
    <inertial>
      <origin
        xyz="4.58320106727639E-08 0.00156153690071638 -5.93446319654967E-08"
        rpy="0 0 0" />
      <mass
        value="0.0602360431222145" />
      <inertia
        ixx="2.53251059631859E-05"
        ixy="-2.35589051033118E-10"
        ixz="5.02101787669809E-09"
        iyy="4.43415236778788E-05"
        iyz="-3.21696424128958E-10"
        izz="2.5311240238302E-05" />
    </inertial>
    <visual>
      <origin
        xyz="0 0 0"
        rpy="0 0 0" />
      <geometry>
        <mesh
          filename="package://mycar00/meshes/br_Link.STL" />
      </geometry>
      <material
        name="">
        <color
          rgba="1 1 1 1" />
      </material>
    </visual>
    <collision>
      <origin
        xyz="0 0 0"
        rpy="0 0 0" />
      <geometry>
        <mesh
          filename="package://mycar00/meshes/br_Link.STL" />
      </geometry>
    </collision>
  </link>
  <joint
    name="br_joint"
    type="continuous">
    <origin
      xyz="-0.0801231358417693 -0.0862813590433901 -0.0315000000000017"
      rpy="0 0 0" />
    <parent
      link="base_link" />
    <child
      link="br_Link" />
    <axis
      xyz="0 1 0" />
  </joint>
  <link
    name="bl_Link">
    <inertial>
      <origin
        xyz="7.23529399310197E-08 -0.00156144868326216 -1.96789797096697E-08"
        rpy="0 0 0" />
      <mass
        value="0.0602355232574738" />
      <inertia
        ixx="2.53044380829734E-05"
        ixy="1.25641215755299E-11"
        ixz="-1.46845910325092E-09"
        iyy="4.43418773184507E-05"
        iyz="-4.68469416212E-12"
        izz="2.53321543363333E-05" />
    </inertial>
    <visual>
      <origin
        xyz="0 0 0"
        rpy="0 0 0" />
      <geometry>
        <mesh
          filename="package://mycar00/meshes/bl_Link.STL" />
      </geometry>
      <material
        name="">
        <color
          rgba="1 1 1 1" />
      </material>
    </visual>
    <collision>
      <origin
        xyz="0 0 0"
        rpy="0 0 0" />
      <geometry>
        <mesh
          filename="package://mycar00/meshes/bl_Link.STL" />
      </geometry>
    </collision>
  </link>
  <joint
    name="bl_joint"
    type="continuous">
    <origin
      xyz="-0.0801231358417693 0.0869186409566067 -0.0315000000000016"
      rpy="0 0 0" />
    <parent
      link="base_link" />
    <child
      link="bl_Link" />
    <axis
      xyz="0 1 0" />
  </joint>
  <link
    name="imu_Link">
    <inertial>
      <origin
        xyz="-0.00036212287209762 -0.0230500268660603 0.00768491749214833"
        rpy="0 0 0" />
      <mass
        value="0.0722083122758557" />
      <inertia
        ixx="4.5394538464552E-05"
        ixy="-8.74659311354103E-07"
        ixz="3.08950355804244E-07"
        iyy="2.05702697480351E-05"
        iyz="4.46643442881401E-07"
        izz="6.2963092786608E-05" />
    </inertial>
    <visual>
      <origin
        xyz="0 0 0"
        rpy="0 0 0" />
      <geometry>
        <mesh
          filename="package://mycar00/meshes/imu_Link.STL" />
      </geometry>
      <material
        name="">
        <color
          rgba="1 1 1 1" />
      </material>
    </visual>
    <collision>
      <origin
        xyz="0 0 0"
        rpy="0 0 0" />
      <geometry>
        <mesh
          filename="package://mycar00/meshes/imu_Link.STL" />
      </geometry>
    </collision>
  </link>
  <joint
    name="imu_joint"
    type="fixed">
    <origin
      xyz="-0.0174584588840668 0.0288186409566084 0.011"
      rpy="0 0 0" />
    <parent
      link="base_link" />
    <child
      link="imu_Link" />
    <axis
      xyz="0 0 0" />
  </joint>
  <link
    name="camera_Link">
    <inertial>
      <origin
        xyz="-0.0014837259776404 0.0350000000000001 6.93889390390723E-18"
        rpy="0 0 0" />
      <mass
        value="0.00469695869809621" />
      <inertia
        ixx="4.56412048936355E-06"
        ixy="-1.83877007339504E-22"
        ixz="-2.87945228785475E-24"
        iyy="1.49254567823211E-07"
        iyz="1.2889947065628E-21"
        izz="4.43679632395855E-06" />
    </inertial>
    <visual>
      <origin
        xyz="0 0 0"
        rpy="0 0 0" />
      <geometry>
        <mesh
          filename="package://mycar00/meshes/camera_Link.STL" />
      </geometry>
      <material
        name="">
        <color
          rgba="1 1 1 1" />
      </material>
    </visual>
    <collision>
      <origin
        xyz="0 0 0"
        rpy="0 0 0" />
      <geometry>
        <mesh
          filename="package://mycar00/meshes/camera_Link.STL" />
      </geometry>
    </collision>
  </link>
  <joint
    name="camera_joint"
    type="fixed">
    <origin
      xyz="0.0937522156393417 -0.0316813590433919 0.0440937058350375"
      rpy="0 0 0" />
    <parent
      link="base_link" />
    <child
      link="camera_Link" />
    <axis
      xyz="0 0 0" />
  </joint>
  <link name="base_footprint"/>
  <joint name="base_joint" type="fixed">
    <origin xyz="0 0 0.066" rpy="0 0 0"/>
    <parent link="base_footprint"/>
    <child link="base_link"/>
  </joint>
</robot>